Workbook
Name _nmw1: [1]lead!$B$2

Sheet Estimate
A1: ESTIMATE
A2: 1. Division | D2: R & B (P) DIV. | F2: NADIAD | G2: JILLA PANCHAYAT | I2: NADIAD
A4: 2. Sub-Division | D4: R & B (P) SUB DIV. | F4: NADIAD | G4: NANI SINCHAI (P) SUB DIV | I4: NADIAD
D5: DEE ATVT PRANT | F5: NADIAD
A6: 3. Sanctioned Estimate No:
A8: 4. Fund Head: | D8: ૧૫ % વિવેકાધીન વર્ષ ૨૦૨૬-૨૭.
A10: 5. Major Head:
A12: 6. Minor Head:
A14: 7. Serviceable Head:
A16: 8. Departmental Head:
A18: Estimated framed in the office of the Taluka Development Officer, Taluka Panchyat, | H18: VASO
A19: for the expenses that will be incurred in the Work Of
A20: કામ નું નામ :- | C20: વસો ગામે ગામની મુખ્ય ગટર લાઇનનું કામ.
A21: Amounting to Rs. | G21: 450000
A22: Administrative approval No.:
D23: Date :
A25: & Technically sanctioned under No.:
D26: Date:
A27: Estimate prepared by | C27: : | D27: Shree A.G.SUTHAR. A.A.E.
A29: Estimate checked by: | C29: =C27 -> : | D29: =D27 -> Shree A.G.SUTHAR. A.A.E.
A31: Call or Authority:
A33: સામાન્ય વર્ણન અને સૈદ્ધાંતિક મંજૂરીની વિગતો.
A34: SR. NO. | B34: 18 | C34: જા.નંબર/વશી- તા. /૦૩/૨૦૨૬.
A35: આ કામ ઉપરોક્ત યોજના હેઠળ મંજૂર થયેલ છે. જે અનવયે સ્થળ સ્થિતિની તપાસ કરીને ગુ. પા. પૂ. અને ગટર વ્યવસ્થા બોર્ડ તેમજ મા. અને મ. વિભાગના પ્રવર્તમાન S.O.R. ના ભાવો મુજબ અંદાજપત્ર તૈયાર કરવામાં આવેલ છે. આ કમના નકશા-અંદાજમાં સ્થળ સ્થિતિ મુજબ ખોદાણ , પાઇપ પ્રોવાઈડ કરી ને ઉતારવી , ચેમ્બર , ફ્રેમ , કવર સાથે તથા તકતીની આઈટમનો સમાવેશ કરેલ છે.
F38: ADD. ASST. ENGINEER
G39: TALUKA PANCHAYAT
G40: =H18 -> VASO

Sheet Abstract
A1: ABSTRACT SHEET
A2: =Estimate!A20 -> કામ નું નામ :- | C2: =Estimate!C20 -> વસો ગામે ગામની મુખ્ય ગટર લાઇનનું કામ.
A3: QTY. | B3: UNIT | C3: ITEM | D3: RATE INCL.1% LABOUR CESS | E3: PER | F3: AMOUNT
A4: =Measurement!K6 -> 0 | B4: Cmt | C4: ITEM NO 1 : Demolition including stacking of serviceable materilas and disposal of unserviceable materials with all lead and lift. (i) R.C.C. work | D4: 1030.81 | E4: Cmt | F4: =A4*D4 -> 0
C5: R&B .S.O.R. P:- 127 I.No. 20002 + 1 % Labour cess (1020.60+10.21=1030.81) | H5: =1020.6 -> 1020.6
A6: =Measurement!K16 -> 106 | B6: Cum | C6: Item No :- 2 Excatation for pipe line trenches incl. all safety provision using site rails & stacking excavated stuff up to a lead of 90 M. cleaing the site etc. complete for lift & strata as specified.(A) in all sorts of soil and soft murrum (a) Upto 1.5 mt. depth | D6: 89 | E6: =B6 -> Cum | F6: =A6*D6 -> 9434 | H6: =H5*1% -> 10.206
C7: G.W.S.S.B.S.O.R. P:- 32 Sec.1 & 2(B) I.No. 1 (a) | H7: =H5+H6 -> 1030.806
C8: Item No :- 3 Providing & supplying ISI standard R.C.C. pipe (or Sulphate Resistance cement) in standard length of following class & diameter suitable for either collar joints or rubber ring joints including all taxes, insurance, transportation, freight charges, octroi, inspection charges,loading, unloading, conveyance to departmental stores, stacking etc. comp. ( IS - 458 / 1989 ) for following dia.d) Class NP2 Test Pressure, 0.7 Kg/sq.cm
C9: G.W.S.S.B.S.O.R. P:- 14 Sec 1&2 (A) I.No. 10.1.B
A10: =Measurement!K19 -> 0 | B10: Rmt | C10: (1) 225 mm. Dia R.C.C. Pipe | D10: 421 | E10: Rmt | F10: =A10*D10 -> 0
A11: =Measurement!K20 -> 0 | B11: Rmt | C11: (2) 300 mm. Dia R.C.C. Pipe | D11: 672 | E11: Rmt | F11: =A11*D11 -> 0
A12: =Measurement!K21 -> 122.5 | B12: Rmt | C12: (3) 450 mm. Dia R.C.C. Pipe | D12: 817 | E12: Rmt | F12: =A12*D12 -> 100082.5
A13: =Measurement!K22 -> 0 | B13: Rmt | C13: (4) 600 mm Dia R.C.C. Pipe | D13: 1331 | E13: Rmt | F13: =A13*D13 -> 0
A14: =Measurement!K23 -> 0 | B14: Rmt | C14: (5) 900 mm Dia. R.C.C. Pipe | D14: 2476 | E14: Rmt | F14: =A14*D14 -> 0
A15: =Measurement!K24 -> 0 | B15: Rmt | C15: (6) 1200 mm Dia. R.C.C. Pipe | D15: 4121 | E15: Rmt | F15: =A15*D15 -> 0
C16: Item No :- 4 Lowing laying & joining R.C.C. pipes in C.M. 1:1 1/2 of follwing diameter in proper position garde aligment as directed by Engg. Incl. Conveyance from store to site of work labour giving hydraulic testing as per ISI code etc. comple incl.
C17: G.W.S.S.B.S.O.R. P:- 39 Sec 1&2 (B) I.No. 11.b
A18: =Measurement!K27 -> 0 | B18: Rmt | C18: (1) 225 mm. Dia R.C.C. Pipe | D18: 88 | E18: =B18 -> Rmt | F18: =A18*D18 -> 0
A19: =Measurement!K28 -> 0 | B19: Rmt | C19: (2) 300 mm. Dia R.C.C. Pipe | D19: 119 | E19: =B19 -> Rmt | F19: =A19*D19 -> 0
A20: =Measurement!K29 -> 122.5 | B20: Rmt | C20: (3) 450 mm. Dia R.C.C. Pipe | D20: 171 | E20: =B20 -> Rmt | F20: =A20*D20 -> 20947.5
A21: =Measurement!K30 -> 0 | B21: Rmt | C21: (4) 600 mm Dia R.C.C. Pipe | D21: 228 | E21: =B21 -> Rmt | F21: =A21*D21 -> 0
A22: =Measurement!K31 -> 0 | B22: Rmt | C22: (5) 900 mm Dia. R.C.C. Pipe | D22: 340 | E22: =B22 -> Rmt | F22: =A22*D22 -> 0
A23: =Measurement!K32 -> 0 | B23: Rmt | C23: (6) 1200 mm Dia. R.C.C. Pipe | D23: 440 | E23: =B23 -> Rmt | F23: =A23*D23 -> 0
C24: Item No:- 5 Constructing of valve chambers in brick or bela stone masonary, locally available in C.M. 1:6. Foundation concrete 150 mm thick in C.C. 1:4:8 of trap metal size 25 mm to 40 mm thick, inside cement plater in C.M. 1:3 and cement pointing outside in C.M. 1:3 and top cover of precast RCC slab 100 mm thick (with key hole in two parts, each with handles or MS Bar etc. comp.e as given size) Upto 1 Mt. depth from G.L. to pipe invert level incl. complete civil works but excluding cost of excavation and refilling. With cast in situ RCC slab in one single piece with fixing of CI - MH Frame and cover (excl. cost of CI -MH Frame & cover) with 23 mm thick brick masonary wall in C.M. 1:6.
C25: (S.O.R. G.W.S.B Pag No:- 101 Sec -2.d It.No:-1 C-2,D-2
A26: =Measurement!K35 -> 0 | B26: No. | C26: Chamber size: 0.60 m x 0.60 m and 1.0 mt deep | D26: 5138 | E26: =B26 -> No. | F26: =A26*D26 -> 0
A27: =Measurement!K36 -> 5 | B27: No. | C27: Chamber size: 0.90 m x 0.90 m and 1.0 mt deep | D27: 7343 | E27: =B27 -> No. | F27: =A27*D27 -> 36715
A28: =Measurement!K37 -> 0 | B28: No. | C28: Chamber size: 1.30 m x 0.90 m and 1.0 mt deep | D28: 8882 | E28: =B28 -> No. | F28: =A28*D28 -> 0
A29: =Measurement!K38 -> 0 | B29: No. | C29: Chamber size: 1.30 m x 1.30 m and 1.0 mt deep | D29: 10698 | E29: =B29 -> No. | F29: =A29*D29 -> 0
A30: =Measurement!K51 -> 82 | B30: Cmt | C30: Item No :- 6 Reflling the pipeline trencher incl. ramming watering comsolidating disposial of surplus stuff as directed withing radius of 3 K.M. | D30: 22 | E30: =B30 -> Cmt | F30: =TRUNC((D31*A30),2) -> 1804
C31: G.W.S.S.B.S.O.R. P:- 40 Sec 1&2 B I.No. 14 | D31: =D30 -> 22
C32: Item No:- 7 R.C.C. precast M.H.Frame & Cover Manufacture, supply & Delivery at store or at site of work precast R.C.C. M.200 Frame & cover suitable to drainage M.H. and as per type design & Drawing including cost of reinforcement M.S.Angle or Flate, curring mold work etc. (A) Heavy Duty
C33: G.W.S.S.B.S.O.R. P:- 16 Sec 1&2 A I.No. 10.4(a)1&2
A34: =Measurement!K54 -> 5 | B34: No | C34: (1) Frame suitable for 50 cm opening of M.H. | D34: 1121 | E34: =B34 -> No | F34: =A34*D34 -> 5605
A35: =Measurement!K55 -> 5 | B35: No | C35: (2) Cover suitable for 50 cm opening of M.H. | D35: 1173 | E35: =B35 -> No | F35: =A35*D35 -> 5865
A36: =Measurement!K59 -> 55.125 | B36: Cmt | C36: Item No. 8 Providing and laying cement concrete 1:2:4 (1- Cement : 2- Coarse sand : 4- graded stone aggregates 20 mm nominal size) and curing complete excluding cost of formwork in (A) Foundation and Plinth | D36: 3652.31 | E36: =B36 -> Cmt | F36: =A36*D36 -> 201333.59
C37: R&B S.O.R. it no 05010AA+1 % labour cess= 3616.15+36.16=3652.31
A38: =Measurement!K63 -> 1 | B38: Cmt | C38: Item No. 9 Providing and fixing Number plate of marble stone of requiered size set in C.M. 1:4 etc. comp. | D38: 306.14 | E38: =B38 -> Cmt | F38: =D38*A38 -> 306.14
C39: ( R & B Sor P. 130 C No 26087 + 1% labour cess = 303.11+3.03=306.14)
A40: Total | F40: =SUM(F4:F39) -> 382092.73
...

Sheet Measurement
A1: MEASUREMENT SHEET
A2: =Abstract!A2 -> કામ નું નામ :- | C2: =Estimate!C20 -> વસો ગામે ગામની મુખ્ય ગટર લાઇનનું કામ.
C3: No | D3: x | E3: L | F3: x | G3: W | H3: x | I3: D | J3: =
A4: =Abstract!C4 -> ITEM NO 1 : Demolition including stacking of serviceable materilas and disposal of unserviceable materials with all lead and lift. (i) R.C.C. work
C5: 1 | D5: x | E5: 0 | F5: x | G5: 0.45 | H5: x | I5: 0.1 | J5: = | K5: =C5*E5*G5*I5 -> 0
G6: Total Qty | J6: = | K6: =K5 -> 0 | L6: Smt
A8: =Abstract!C6 -> Item No :- 2 Excatation for pipe line trenches incl. all safety provision using site rails & stacking excavated stuff up to a lead of 90 M. cleaing the site etc. complete for lift & strata as specified.(A) in all sorts of soil and soft murrum (a) Upto 1.5 mt. depth
B9: (1) 225 mm dia. | C9: 1 | D9: X | E9: 0 | F9: X | G9: 0.45 | H9: X | I9: =0.225+0.6 -> 0.825 | J9: = | K9: =C9*E9*G9*I9 -> 0 | L9: Cmt
B10: (2) 300 mm dia. | C10: 1 | D10: X | E10: 0 | F10: X | G10: 0.45 | H10: X | I10: =0.3+0.6 -> 0.9 | J10: = | K10: =C10*E10*G10*I10 -> 0 | L10: "
B11: (3) 450 mm dia. | C11: 1 | D11: X | E11: 122.5 | F11: X | G11: 0.75 | H11: X | I11: =0.45+0.7 -> 1.15 | J11: = | K11: =C11*E11*G11*I11 -> 105.65625 | L11: "
B12: (4) 600 mm dia. | C12: 1 | D12: X | E12: 0 | F12: X | G12: 0.9 | H12: X | I12: =0.6+0.75 -> 1.35 | J12: = | K12: =C12*E12*G12*I12 -> 0 | L12: "
B13: (5) 900 mm dia. | C13: 1 | D13: X | E13: 0 | F13: X | G13: 1.2 | H13: X | I13: =0.9+0.9 -> 1.8 | J13: = | K13: =C13*E13*G13*I13 -> 0 | L13: "
B14: (6) 1200 mm dia. | C14: 1 | D14: X | E14: 0 | F14: X | G14: 1.5 | H14: X | I14: =1.2+1 -> 2.2 | J14: = | K14: =C14*E14*G14*I14 -> 0 | L14: "
G15: Total Qty | J15: = | K15: =SUM(K9:K14) -> 105.65625 | L15: Cmt
G16: Say | J16: = | K16: =ROUNDUP(K15,0) -> 106 | L16: Cmt
A18: =Abstract!C8 -> Item No :- 3 Providing & supplying ISI standard R.C.C. pipe (or Sulphate Resistance cement) in standard length of following class & diameter suitable for either collar joints or rubber ring joints including all taxes, insurance, transportation, freight charges, octroi, inspection charges,loading, unloading, conveyance to departmental stores, stacking etc. comp. ( IS - 458 / 1989 ) for following dia.d) Class NP2 Test Pressure, 0.7 Kg/sq.cm
B19: (1) 225 mm dia. | C19: =C9 -> 1 | D19: X | E19: =E9 -> 0 | J19: = | K19: =E19 -> 0 | L19: Rmt.
B20: (2) 300 mm dia. | C20: =C10 -> 1 | D20: X | E20: =E10 -> 0 | J20: = | K20: =E20 -> 0 | L20: Rmt.
B21: (3) 450 mm dia. | C21: =C11 -> 1 | D21: X | E21: =E11 -> 122.5 | J21: = | K21: =E21 -> 122.5 | L21: Rmt.
B22: (4) 600 mm dia. | C22: =C12 -> 1 | D22: X | E22: =E12 -> 0 | J22: = | K22: =E22 -> 0 | L22: Rmt.
B23: (5) 900 mm dia. | C23: =C13 -> 1 | D23: X | E23: =E13 -> 0 | J23: = | K23: =E23 -> 0 | L23: Rmt.
B24: (6) 1200 mm dia. | C24: =C14 -> 1 | D24: X | E24: =E14 -> 0 | J24: = | K24: =E24 -> 0 | L24: Rmt.
A26: =Abstract!C16 -> Item No :- 4 Lowing laying & joining R.C.C. pipes in C.M. 1:1 1/2 of follwing diameter in proper position garde aligment as directed by Engg. Incl. Conveyance from store to site of work labour giving hydraulic testing as per ISI code etc. comple incl.
B27: (1) 225 mm dia. | C27: =C19 -> 1 | D27: X | E27: =E19 -> 0 | J27: = | K27: =C27*E27 -> 0 | L27: Rmt.
B28: (2) 300 mm dia. | C28: =C20 -> 1 | D28: X | E28: =E20 -> 0 | J28: = | K28: =C28*E28 -> 0 | L28: Rmt.
B29: (3) 450 mm dia. | C29: =C21 -> 1 | D29: X | E29: =E21 -> 122.5 | J29: = | K29: =C29*E29 -> 122.5 | L29: Rmt.
B30: (4) 600 mm dia. | C30: =C22 -> 1 | D30: X | E30: =E22 -> 0 | J30: = | K30: =C30*E30 -> 0 | L30: Rmt.
B31: (5) 900 mm dia. | C31: =C23 -> 1 | D31: X | E31: =E23 -> 0 | J31: = | K31: =C31*E31 -> 0 | L31: Rmt.
B32: (6) 1200 mm dia. | C32: =C24 -> 1 | D32: X | E32: =E24 -> 0 | J32: = | K32: =C32*E32 -> 0 | L32: Rmt.
A34: =Abstract!C24 -> Item No:- 5 Constructing of valve chambers in brick or bela stone masonary, locally available in C.M. 1:6. Foundation concrete 150 mm thick in C.C. 1:4:8 of trap metal size 25 mm to 40 mm thick, inside cement plater in C.M. 1:3 and cement pointing outside in C.M. 1:3 and top cover of precast RCC slab 100 mm thick (with key hole in two parts, each with handles or MS Bar etc. comp.e as given size) Upto 1 Mt. depth from G.L. to pipe invert level incl. complete civil works but excluding cost of excavation and refilling. With cast in situ RCC slab in one single piece with fixing of CI - MH Frame and cover (excl. cost of CI -MH Frame & cover) with 23 mm thick brick masonary wall in C.M. 1:6.
B35: (1) 0.60x0.60x1.00 mt deep | C35: 1 | D35: X | E35: 0 | J35: = | K35: =E35 -> 0 | L35: No.
B36: (2) 0.90x0.90x1.00 mt deep | C36: 1 | D36: X | E36: 5 | J36: = | K36: =E36 -> 5 | L36: No.
B37: (3) 1.30x0.90x1.00 mt deep | C37: 1 | D37: X | E37: 0 | J37: = | K37: =E37 -> 0 | L37: No.
B38: (4) 1.30x1.30x1.00 mt deep | C38: 1 | D38: X | E38: 0 | J38: = | K38: =E38 -> 0 | L38: No.
A40: =Abstract!C30 -> Item No :- 6 Reflling the pipeline trencher incl. ramming watering comsolidating disposial of surplus stuff as directed withing radius of 3 K.M.
B42: Deduction | G42: Excavated Qty. | J42: = | K42: =K16 -> 106 | L42: Cmt.
B43: (1) 225 mm dia. | C43: 0.785 | D43: X | E43: 0.3 | F43: X | G43: =E43 -> 0.3 | H43: X | I43: =E9 -> 0 | J43: = | K43: =C43*E43*G43*I43 -> 0 | L43: Cmt
B44: (2) 300 mm dia. | C44: 0.785 | D44: X | E44: 0.35 | F44: X | G44: =E44 -> 0.35 | H44: X | I44: =E10 -> 0 | J44: = | K44: =C44*E44*G44*I44 -> 0 | L44: Cmt
B45: (2) 450 mm dia. | C45: 0.785 | D45: X | E45: 0.5 | F45: X | G45: =E45 -> 0.5 | H45: X | I45: =E11 -> 122.5 | J45: = | K45: =C45*E45*G45*I45 -> 24.040625 | L45: Cmt
B46: (4) 600 mm dia. | C46: 0.785 | D46: X | E46: 0.65 | F46: X | G46: =E46 -> 0.65 | H46: X | I46: =E12 -> 0 | J46: = | K46: =C46*E46*G46*I46 -> 0 | L46: Cmt
...

Sheet TEST-SITE
A1: =Abstract!A2 -> કામ નું નામ :- | B1: =Abstract!C2 -> વસો ગામે ગામની મુખ્ય ગટર લાઇનનું કામ.
A3: SCHEUDULE OF TESTING
A4: Sr. No | B4: Item | C4: No of testing required | E4: Approved Rate | G4: Amount
A5: 1 | B5: Bricks | C5: 0 | D5: x | E5: 578 | F5: = | G5: =C5*E5 -> 0
A6: 2 | B6: Sand | C6: 0 | D6: x | E6: 388 | F6: = | G6: =C6*E6 -> 0
A7: 3 | B7: Cement | C7: 0 | D7: x | E7: 788 | F7: = | G7: =C7*E7 -> 0
A8: 4 | B8: Cube | C8: 0 | D8: x | E8: 238 | F8: = | G8: =C8*E8 -> 0
A9: 5 | B9: B.T.Kapchi | C9: 0 | D9: x | E9: 546 | F9: = | G9: =C9*E9 -> 0
A10: 6 | B10: Metal | C10: 0 | D10: x | E10: 696 | F10: = | G10: =C10*E10 -> 0
A11: 7 | B11: Paving Blocks | C11: 0 | D11: x | E11: 220 | F11: = | G11: =C11*E11 -> 0
A12: 8 | B12: Steel | C12: 0 | D12: x | E12: 294 | F12: = | G12: =C12*E12 -> 0
A13: 9 | B13: Pipe Line | C13: 0 | D13: x | E13: 300 | F13: = | G13: =C13*E13 -> 0
A14: 10 | B14: Gutter Pipe | C14: 1 | D14: x | E14: 300 | F14: = | G14: =C14*E14 -> 300
G15: =SUM(G5:G14) -> 300
A17: SITE PLAN
G34: A.A.E.
G35: TALUKA PANCHAYAT
G36: =Abstract!A46 -> VASO
